<?xml version="1.0"?>
<robot xmlns:xacro="http://www.ros.org/wiki/xacro"  name="wheel">
    <xacro:macro name="wheel" params="fb lr parent translateX translateY flipY">
        <link name="${}_${}_wheel">
        <visual>
            <origin xyz="0.0 0.0 0.0" rpy="0.0 0.0 0.0"/>
            <geometry>
                <cylinder radius="0.0" length="0.0"/>
            </geometry>
            <material name="DarkGray"/>
        </visual> 
        <collision>
            <origin xyz="0.0 0.0 0.0" rpy="0.0 0.0 0.0"/>
            <geometry>
                <cylinder radius="0.0" length="0.0"/>
            </geometry>
        </collision>
        <inertial>
            <mass value="0.0"/>
            <origin xyz="0.0 0.0 0.0"/>
            <cylinder_inertia />
        </inertial>    
        </link>
        <gazebo reference="${fb}_${lr}_wheel">
            <mu1 value="1.0"/>
            <mu2 value="1.0"/>
            <kp value="10000000.0"/>
            <kd value="1.0"/>
            <fdir1 value="1 0 0"/>
            <material>Gazebo/Grey</material>
            <turnGravityOff>false</turnGravityOff>
        </gazebo>
        <joint name="${fb}_${lr}_wheel_joint" type="continuous">
            <parent link="{parent}"/>
            <child link="${fb}_${lr}_wheel"/> 
            <origin xyz="0.0 0.0 0.0" rpy="0.0 0.0 0.0"/>
            <axis xyz="0.0 0.0 0.0"/>
            <limit  effort="100.0" velocity="100.0"/>
            <joint_properties damping="0.0" friction="0.0" />
        </joint>    
        <transmission name="${fb}_${lr}_wheel_joint_trans">
            <type>transmission_interface/SimpleTransmission</type>
            <joint name="${fb}_${lr}_wheel_joint"/>
            <actuator name="${fb}_${lr}_wheel_joint_motor">
                <hardwareinterface>EffortJointInterface</hardwareinterface>
                <mechanicalReduction>1</mechanicalReduction>
            </actuator>
        </transmission>
    </xacro:macro>
</robot>
